Workbook

Sheet Instellingen
A1: Windsor.ai-querybuilder — nieuwe klant
A2: Vul de gele cellen in. Elk exporttabblad bouwt daaruit de URL, de taaknaam en de tabnaam. De api_key blijft altijd leeg: plak die pas in Windsor.
A3: Klantcode | B3: mayday | C3: Kleine letters, zoals in CLIENTS. Komt in taaknaam en tabnaam.
A4: date_preset | B4: last_30d | C4: Windsor-periode per run (bv. last_30d, last_90d). Leeg = geen periode in de URL.
A5: _field_headers | B5: names | C5: names = leesbare koppen (zoals de bestaande exports), ids = veld-id's als kop. Het dashboard leest beide.
A6: Conversiedoel (GA4-eventnaam) | C6: Zelfde waarde als 'Conversiedoel' in de Config-tab. Vult het veld conversions_<event> in de GA4-tabs.
A8: Account-id's (Windsor select_accounts) — leeg laten = geen select_accounts in de URL
A9: Instagram account-id | B9: 17841452604543901 | C9: Numerieke IG-id (Windsor select_accounts), niet de gebruikersnaam.
A10: Facebook pagina-id | C10: Connector facebook_organic.
A11: Meta Ads account-id | C11: Zoals Windsor hem toont, zonder act_.
A12: GA4 property-id | C12: Cijferreeks, bv. 491908260. Zelfde als 'GA4 property' in de Config-tab.
A13: Search Console site | C13: sc-domain:merk.be of https://www.merk.be/ — exact zoals Windsor hem toont.
A14: Google Ads customer-id | C14: Zoals Windsor hem toont (met of zonder streepjes, volg Windsor).
A15: Klaviyo account-id | C15: Alleen bij Klaviyo.
A16: Mailerlite account-id | C16: Alleen bij Mailerlite.
A18: Delen met het service-account (Viewer): | B18: performance-agent@performance-agent-493301.iam.gserviceaccount.com
A19: Deel een Windsor-datasheet nooit met een klant: de Queries-tab bevat de api_key.
A21: Exporttab | B21: Connector | C21: Status | D21: Dashboardblok | E21: Taaknaam (Task name) | F21: Tabnaam (Sheet Name)
A22: Instagram Org | B22: instagram | C22: Aanbevolen | D22: Social → Instagram | E22: ='Instagram Org'!$B$4 | F22: ='Instagram Org'!$B$5
A23: Facebook Org | B23: facebook_organic | C23: Aanbevolen | D23: Social → Facebook | E23: ='Facebook Org'!$B$4 | F23: ='Facebook Org'!$B$5
A24: Meta Ads campagnes | B24: facebook | C24: Aanbevolen | D24: Ads → Meta (trend, KPI's, funnel) + ROAS | E24: ='Meta Ads campagnes'!$B$4 | F24: ='Meta Ads campagnes'!$B$5
A25: Meta Ads advertenties | B25: facebook | C25: Aanbevolen | D25: Ads → Meta (advertenties, creatie, video, conversies) | E25: ='Meta Ads advertenties'!$B$4 | F25: ='Meta Ads advertenties'!$B$5
A26: Meta Ads doelgroep | B26: facebook | C26: Optioneel (anders live) | D26: Ads → Meta doelgroepblok (aandelen) | E26: ='Meta Ads doelgroep'!$B$4 | F26: ='Meta Ads doelgroep'!$B$5
A27: Meta Ads regio | B27: facebook | C27: Optioneel (anders live) | D27: Ads → Meta regio | E27: ='Meta Ads regio'!$B$4 | F27: ='Meta Ads regio'!$B$5
A28: Meta Ads asset titel | B28: facebook | C28: Optioneel (anders live) | D28: Ads → Meta creatieve varianten | E28: ='Meta Ads asset titel'!$B$4 | F28: ='Meta Ads asset titel'!$B$5
A29: Meta Ads asset body | B29: facebook | C29: Optioneel (anders live) | D29: Ads → Meta creatieve varianten | E29: ='Meta Ads asset body'!$B$4 | F29: ='Meta Ads asset body'!$B$5
A30: Meta Ads asset CTA | B30: facebook | C30: Optioneel (anders live) | D30: Ads → Meta creatieve varianten | E30: ='Meta Ads asset CTA'!$B$4 | F30: ='Meta Ads asset CTA'!$B$5
A31: Meta Ads asset image | B31: facebook | C31: Optioneel (anders live) | D31: Ads → Meta creatieve varianten | E31: ='Meta Ads asset image'!$B$4 | F31: ='Meta Ads asset image'!$B$5
A32: Meta Ads asset video | B32: facebook | C32: Optioneel (anders live) | D32: Ads → Meta creatieve varianten | E32: ='Meta Ads asset video'!$B$4 | F32: ='Meta Ads asset video'!$B$5
A33: GA4 dag | B33: googleanalytics4 | C33: Aanbevolen | D33: Website (totalen, dagreeks) + ROAS (GA4-omzet) + Doelen | E33: ='GA4 dag'!$B$4 | F33: ='GA4 dag'!$B$5
A34: GA4 kanaal | B34: googleanalytics4 | C34: Aanbevolen | D34: Website (donut, bronnen) + ROAS-kanaalsplitsing + AI-verkeer | E34: ='GA4 kanaal'!$B$4 | F34: ='GA4 kanaal'!$B$5
A35: GA4 landing | B35: googleanalytics4 | C35: Aanbevolen | D35: Website → landingspagina's | E35: ='GA4 landing'!$B$4 | F35: ='GA4 landing'!$B$5
A36: GA4 doelgroep | B36: googleanalytics4 | C36: Alleen klanten zonder Windsor-sleutel | D36: Website → Doelgroep (dashboard haalt dit normaal live) | E36: ='GA4 doelgroep'!$B$4 | F36: ='GA4 doelgroep'!$B$5
A37: Search Console dag | B37: searchconsole | C37: Aanbevolen | D37: Website → organisch zoeken (totalen) | E37: ='Search Console dag'!$B$4 | F37: ='Search Console dag'!$B$5
A38: Search Console query | B38: searchconsole | C38: Aanbevolen | D38: Website → zoekopdrachten | E38: ='Search Console query'!$B$4 | F38: ='Search Console query'!$B$5
A39: Search Console pagina | B39: searchconsole | C39: Optioneel (anders live) | D39: Website → pagina's | E39: ='Search Console pagina'!$B$4 | F39: ='Search Console pagina'!$B$5
A40: Google Ads campagnes | B40: google_ads | C40: Aanbevolen | D40: Ads → Google Ads + ROAS | E40: ='Google Ads campagnes'!$B$4 | F40: ='Google Ads campagnes'!$B$5
A41: Google Ads vertoningsaandeel | B41: google_ads | C41: Aanbevolen | D41: Ads → Google Ads vertoningsaandeel | E41: ='Google Ads vertoningsaandeel'!$B$4 | F41: ='Google Ads vertoningsaandeel'!$B$5
A42: Google Ads zoektermen | B42: google_ads | C42: Aanbevolen | D42: Ads → Google Ads zoektermen (30 d) | E42: ='Google Ads zoektermen'!$B$4 | F42: ='Google Ads zoektermen'!$B$5
A43: Google Ads apparaat | B43: google_ads | C43: Aanbevolen | D43: Ads → Google Ads apparaten | E43: ='Google Ads apparaat'!$B$4 | F43: ='Google Ads apparaat'!$B$5
...

Sheet Instagram Org
A1: Windsor-export: Instagram Organic | C1: Status: Aanbevolen · Social → Instagram
A2: Connector | B2: instagram
A3: Account-id (uit Instellingen) | B3: =Instellingen!$B$9
A4: Taaknaam (Task name) | B4: ="Windsor - Sheets - Instagram Organic - "&Instellingen!$B$3
A5: Tabnaam (Sheet Name) | B5: ="Instagram Org - "&Instellingen!$B$3&" - windsor.ai" | C5: Herkenning in api/_sheetdata.js gaat op bron + niveau in deze naam; hou het voorstel aan.
A6: Columns to Match (rows to replace) | B6: date | C6: Voorstel; zoals bij de bestaande exports.
A7: Schedule | B7: Daily · 00:00 UTC · Target Cell A1 · Authentication: Google Account
A8: Query (gegenereerd — api_key blijft leeg) | B8: ="https://connectors.windsor.ai/"&$B$2&"?api_key="&IF(Instellingen!$B$4<>"","&date_preset="&Instellingen!$B$4,"")&"&fields="&_xlfn.TEXTJOIN(",",TRUE,$D$12:$D$80)&IF($B$3<>"","&select_accounts="&$B$3,"")&IF(Instellingen!$B$5<>"","&_field_headers="&Instellingen!$B$5,"")
A9: Aantal velden in de query | B9: =COUNTIF($C$12:$C$80,"x")
A11: Veld (Windsor-id) | B11: Gebruik in het dashboard | C11: Opnemen (x) | D11: → query
A12: date | B12: Datumkolom: 'Columns to Match' en periodefilter | C12: x | D12: =IF(AND($C12="x",$A12<>""),$A12,"")
A13: account_id | B13: Accountcontrole: alleen rijen van dit account tellen mee | C13: x | D13: =IF(AND($C13="x",$A13<>""),$A13,"")
A14: account_name | B14: Idem, leesbaar | C14: x | D14: =IF(AND($C14="x",$A14<>""),$A14,"")
A15: media_id | B15: Identiteit van de post (verplicht voor de sheet) | C15: x | D15: =IF(AND($C15="x",$A15<>""),$A15,"")
A16: timestamp | B16: Publicatiedatum (verplicht voor de sheet) | C16: x | D16: =IF(AND($C16="x",$A16<>""),$A16,"")
A17: media_caption | B17: Caption in de bibliotheek | C17: x | D17: =IF(AND($C17="x",$A17<>""),$A17,"")
A18: media_type | B18: IMAGE / VIDEO / CAROUSEL_ALBUM | C18: x | D18: =IF(AND($C18="x",$A18<>""),$A18,"")
A19: media_product_type | B19: FEED / REELS / STORY — stuurt post vs. reel (verplicht) | C19: x | D19: =IF(AND($C19="x",$A19<>""),$A19,"")
A20: media_thumbnail_url | B20: Thumbnail | C20: x | D20: =IF(AND($C20="x",$A20<>""),$A20,"")
A21: media_url | B21: Media-URL | C21: x | D21: =IF(AND($C21="x",$A21<>""),$A21,"")
A22: media_permalink | B22: Link naar de post | C22: x | D22: =IF(AND($C22="x",$A22<>""),$A22,"")
A23: media_like_count | B23: Likes | C23: x | D23: =IF(AND($C23="x",$A23<>""),$A23,"")
... A32: media_reel_total_interactions | B32: Reels: interacties | C32: x | D32: =IF(AND($C32="x",$A32<>""),$A32,"")
A33: followers_count | B33: Optioneel: volgers (niet gebruikt door het dashboard) | D33: =IF(AND($C33="x",$A33<>""),$A33,"")
A34: source | B34: Optioneel: bron (niet gebruikt) | D34: =IF(AND($C34="x",$A34<>""),$A34,"")
A35: media_profile_visits | B35: Optioneel: profielbezoeken (niet gebruikt) | D35: =IF(AND($C35="x",$A35<>""),$A35,"")
A36: media_shortcode | B36: Optioneel: shortcode (niet gebruikt) | D36: =IF(AND($C36="x",$A36<>""),$A36,"")
A37: Eigen veld toevoegen: zet hieronder het Windsor-veld-id in kolom A en een x in kolom C (tot rij 80).
D38: =IF(AND($C38="x",$A38<>""),$A38,"")
D39: =IF(AND($C39="x",$A39<>""),$A39,"")
D40: =IF(AND($C40="x",$A40<>""),$A40,"")
D41: =IF(AND($C41="x",$A41<>""),$A41,"")
D42: =IF(AND($C42="x",$A42<>""),$A42,"")
D43: =IF(AND($C43="x",$A43<>""),$A43,"")
D44: =IF(AND($C44="x",$A44<>""),$A44,"")
D45: =IF(AND($C45="x",$A45<>""),$A45,"")
D46: =IF(AND($C46="x",$A46<>""),$A46,"")
D47: =IF(AND($C47="x",$A47<>""),$A47,"")
D48: =IF(AND($C48="x",$A48<>""),$A48,"")
D49: =IF(AND($C49="x",$A49<>""),$A49,"")
...

Sheet Facebook Org
A1: Windsor-export: Facebook Organic | C1: Status: Aanbevolen · Social → Facebook
A2: Connector | B2: facebook_organic
A3: Account-id (uit Instellingen) | B3: =Instellingen!$B$10
A4: Taaknaam (Task name) | B4: ="Windsor - Sheets - Facebook Organic - "&Instellingen!$B$3
A5: Tabnaam (Sheet Name) | B5: ="Facebook Org - "&Instellingen!$B$3&" - windsor.ai" | C5: Herkenning in api/_sheetdata.js gaat op bron + niveau in deze naam; hou het voorstel aan.
A6: Columns to Match (rows to replace) | B6: date | C6: Voorstel; zoals bij de bestaande exports.
A7: Schedule | B7: Daily · 00:00 UTC · Target Cell A1 · Authentication: Google Account
A8: Query (gegenereerd — api_key blijft leeg) | B8: ="https://connectors.windsor.ai/"&$B$2&"?api_key="&IF(Instellingen!$B$4<>"","&date_preset="&Instellingen!$B$4,"")&"&fields="&_xlfn.TEXTJOIN(",",TRUE,$D$12:$D$80)&IF($B$3<>"","&select_accounts="&$B$3,"")&IF(Instellingen!$B$5<>"","&_field_headers="&Instellingen!$B$5,"")
A9: Aantal velden in de query | B9: =COUNTIF($C$12:$C$80,"x")
A11: Veld (Windsor-id) | B11: Gebruik in het dashboard | C11: Opnemen (x) | D11: → query
A12: date | B12: Datumkolom: 'Columns to Match' en periodefilter | C12: x | D12: =IF(AND($C12="x",$A12<>""),$A12,"")
A13: account_id | B13: Accountcontrole: alleen rijen van dit account tellen mee | C13: x | D13: =IF(AND($C13="x",$A13<>""),$A13,"")
A14: account_name | B14: Idem, leesbaar | C14: x | D14: =IF(AND($C14="x",$A14<>""),$A14,"")
A15: post_id | B15: Identiteit van de post (verplicht) | C15: x | D15: =IF(AND($C15="x",$A15<>""),$A15,"")
A16: post_created_time | B16: Publicatiedatum (verplicht) | C16: x | D16: =IF(AND($C16="x",$A16<>""),$A16,"")
A17: type | B17: photo / album / video_inline / video_direct_response — reels = video | C17: x | D17: =IF(AND($C17="x",$A17<>""),$A17,"")
A18: post_message | B18: Tekst van de post | C18: x | D18: =IF(AND($C18="x",$A18<>""),$A18,"")
A19: permalink_url | B19: Link | C19: x | D19: =IF(AND($C19="x",$A19<>""),$A19,"")
A20: full_picture | B20: Afbeelding | C20: x | D20: =IF(AND($C20="x",$A20<>""),$A20,"")
A21: post_impressions | B21: Vertoningen | C21: x | D21: =IF(AND($C21="x",$A21<>""),$A21,"")
A22: post_impressions_unique | B22: Bereik | C22: x | D22: =IF(AND($C22="x",$A22<>""),$A22,"")
A23: post_reactions_total | B23: Reacties (likes e.d.) | C23: x | D23: =IF(AND($C23="x",$A23<>""),$A23,"")
... A26: post_video_views | B26: Videoweergaven | C26: x | D26: =IF(AND($C26="x",$A26<>""),$A26,"")
A27: Eigen veld toevoegen: zet hieronder het Windsor-veld-id in kolom A en een x in kolom C (tot rij 80).
D28: =IF(AND($C28="x",$A28<>""),$A28,"")
D29: =IF(AND($C29="x",$A29<>""),$A29,"")
D30: =IF(AND($C30="x",$A30<>""),$A30,"")
D31: =IF(AND($C31="x",$A31<>""),$A31,"")
D32: =IF(AND($C32="x",$A32<>""),$A32,"")
D33: =IF(AND($C33="x",$A33<>""),$A33,"")
D34: =IF(AND($C34="x",$A34<>""),$A34,"")
D35: =IF(AND($C35="x",$A35<>""),$A35,"")
D36: =IF(AND($C36="x",$A36<>""),$A36,"")
D37: =IF(AND($C37="x",$A37<>""),$A37,"")
D38: =IF(AND($C38="x",$A38<>""),$A38,"")
D39: =IF(AND($C39="x",$A39<>""),$A39,"")
... D80: =IF(AND($C80="x",$A80<>""),$A80,"")

Sheet Meta Ads campagnes
A1: Windsor-export: Meta Ads campagnes | C1: Status: Aanbevolen · Ads → Meta (trend, KPI's, funnel) + ROAS
A2: Connector | B2: facebook
A3: Account-id (uit Instellingen) | B3: =Instellingen!$B$11
A4: Taaknaam (Task name) | B4: ="Windsor - Sheets - Meta Ads campagnes - "&Instellingen!$B$3
A5: Tabnaam (Sheet Name) | B5: ="Meta Ads - campagnes - "&Instellingen!$B$3&" - windsor.ai" | C5: Herkenning in api/_sheetdata.js gaat op bron + niveau in deze naam; hou het voorstel aan.
A6: Columns to Match (rows to replace) | B6: date | C6: Voorstel; zoals bij de bestaande exports.
A7: Schedule | B7: Daily · 00:00 UTC · Target Cell A1 · Authentication: Google Account
A8: Query (gegenereerd — api_key blijft leeg) | B8: ="https://connectors.windsor.ai/"&$B$2&"?api_key="&IF(Instellingen!$B$4<>"","&date_preset="&Instellingen!$B$4,"")&"&fields="&_xlfn.TEXTJOIN(",",TRUE,$D$12:$D$80)&IF($B$3<>"","&select_accounts="&$B$3,"")&IF(Instellingen!$B$5<>"","&_field_headers="&Instellingen!$B$5,"")
A9: Aantal velden in de query | B9: =COUNTIF($C$12:$C$80,"x")
A11: Veld (Windsor-id) | B11: Gebruik in het dashboard | C11: Opnemen (x) | D11: → query
A12: date | B12: Datumkolom: 'Columns to Match' en periodefilter | C12: x | D12: =IF(AND($C12="x",$A12<>""),$A12,"")
A13: account_id | B13: Accountcontrole: alleen rijen van dit account tellen mee | C13: x | D13: =IF(AND($C13="x",$A13<>""),$A13,"")
A14: account_name | B14: Idem, leesbaar | C14: x | D14: =IF(AND($C14="x",$A14<>""),$A14,"")
A15: campaign_id | B15: Campagne-id | C15: x | D15: =IF(AND($C15="x",$A15<>""),$A15,"")
A16: campaign_name | B16: Campagnenaam (kop 'Campaign') | C16: x | D16: =IF(AND($C16="x",$A16<>""),$A16,"")
A17: campaign_objective | B17: Campagnedoel (funnel-blok) | C17: x | D17: =IF(AND($C17="x",$A17<>""),$A17,"")
A18: impressions | B18: Vertoningen | C18: x | D18: =IF(AND($C18="x",$A18<>""),$A18,"")
A19: reach | B19: Bereik per dag (niet ontdubbeld over de periode) | C19: x | D19: =IF(AND($C19="x",$A19<>""),$A19,"")
A20: clicks | B20: Kliks | C20: x | D20: =IF(AND($C20="x",$A20<>""),$A20,"")
A21: spend | B21: Kosten (kop 'Amount Spent') | C21: x | D21: =IF(AND($C21="x",$A21<>""),$A21,"")
A22: cpm | B22: CPM | C22: x | D22: =IF(AND($C22="x",$A22<>""),$A22,"")
A23: cpc | B23: CPC | C23: x | D23: =IF(AND($C23="x",$A23<>""),$A23,"")
A24: ctr | B24: CTR | C24: x | D24: =IF(AND($C24="x",$A24<>""),$A24,"")
A25: Eigen veld toevoegen: zet hieronder het Windsor-veld-id in kolom A en een x in kolom C (tot rij 80).
D26: =IF(AND($C26="x",$A26<>""),$A26,"")
D27: =IF(AND($C27="x",$A27<>""),$A27,"")
D28: =IF(AND($C28="x",$A28<>""),$A28,"")
D29: =IF(AND($C29="x",$A29<>""),$A29,"")
D30: =IF(AND($C30="x",$A30<>""),$A30,"")
D31: =IF(AND($C31="x",$A31<>""),$A31,"")
D32: =IF(AND($C32="x",$A32<>""),$A32,"")
D33: =IF(AND($C33="x",$A33<>""),$A33,"")
D34: =IF(AND($C34="x",$A34<>""),$A34,"")
D35: =IF(AND($C35="x",$A35<>""),$A35,"")
D36: =IF(AND($C36="x",$A36<>""),$A36,"")
D37: =IF(AND($C37="x",$A37<>""),$A37,"")
... D80: =IF(AND($C80="x",$A80<>""),$A80,"")

Sheet Meta Ads advertenties
A1: Windsor-export: Meta Ads advertenties | C1: Status: Aanbevolen · Ads → Meta (advertenties, creatie, video, conversies)
A2: Connector | B2: facebook
A3: Account-id (uit Instellingen) | B3: =Instellingen!$B$11
A4: Taaknaam (Task name) | B4: ="Windsor - Sheets - Meta Ads advertenties - "&Instellingen!$B$3
A5: Tabnaam (Sheet Name) | B5: ="Meta Ads - advertenties - "&Instellingen!$B$3&" - windsor.ai" | C5: Herkenning in api/_sheetdata.js gaat op bron + niveau in deze naam; hou het voorstel aan.
A6: Columns to Match (rows to replace) | B6: date | C6: Voorstel; zoals bij de bestaande exports.
A7: Schedule | B7: Daily · 00:00 UTC · Target Cell A1 · Authentication: Google Account
A8: Query (gegenereerd — api_key blijft leeg) | B8: ="https://connectors.windsor.ai/"&$B$2&"?api_key="&IF(Instellingen!$B$4<>"","&date_preset="&Instellingen!$B$4,"")&"&fields="&_xlfn.TEXTJOIN(",",TRUE,$D$12:$D$80)&IF($B$3<>"","&select_accounts="&$B$3,"")&IF(Instellingen!$B$5<>"","&_field_headers="&Instellingen!$B$5,"")
A9: Aantal velden in de query | B9: =COUNTIF($C$12:$C$80,"x")
A11: Veld (Windsor-id) | B11: Gebruik in het dashboard | C11: Opnemen (x) | D11: → query
A12: date | B12: Datumkolom: 'Columns to Match' en periodefilter | C12: x | D12: =IF(AND($C12="x",$A12<>""),$A12,"")
A13: account_id | B13: Accountcontrole: alleen rijen van dit account tellen mee | C13: x | D13: =IF(AND($C13="x",$A13<>""),$A13,"")
A14: account_name | B14: Idem, leesbaar | C14: x | D14: =IF(AND($C14="x",$A14<>""),$A14,"")
A15: ad_id | B15: Identiteit van de advertentie (verplicht; blijft tekst) | C15: x | D15: =IF(AND($C15="x",$A15<>""),$A15,"")
A16: ad_name | B16: Advertentienaam | C16: x | D16: =IF(AND($C16="x",$A16<>""),$A16,"")
A17: campaign_id | B17: Campagne (geen fijnere korrel: één ad hoort bij één campagne) | C17: x | D17: =IF(AND($C17="x",$A17<>""),$A17,"")
A18: campaign_name | B18: Campagnenaam | C18: x | D18: =IF(AND($C18="x",$A18<>""),$A18,"")
A19: image_url | B19: Afbeelding | C19: x | D19: =IF(AND($C19="x",$A19<>""),$A19,"")
A20: impressions | B20: Vertoningen | C20: x | D20: =IF(AND($C20="x",$A20<>""),$A20,"")
A21: reach | B21: Bereik per dag | C21: x | D21: =IF(AND($C21="x",$A21<>""),$A21,"")
A22: clicks | B22: Kliks | C22: x | D22: =IF(AND($C22="x",$A22<>""),$A22,"")
A23: spend | B23: Kosten | C23: x | D23: =IF(AND($C23="x",$A23<>""),$A23,"")
... A55: instagram_profile_visits | B55: Profielbezoeken via de ad | C55: x | D55: =IF(AND($C55="x",$A55<>""),$A55,"")
A56: frequency | B56: NIET uit dagrijen te ontdubbelen — dashboard haalt dit live; laat uit | D56: =IF(AND($C56="x",$A56<>""),$A56,"")
A57: Eigen veld toevoegen: zet hieronder het Windsor-veld-id in kolom A en een x in kolom C (tot rij 80).
D58: =IF(AND($C58="x",$A58<>""),$A58,"")
D59: =IF(AND($C59="x",$A59<>""),$A59,"")
D60: =IF(AND($C60="x",$A60<>""),$A60,"")
D61: =IF(AND($C61="x",$A61<>""),$A61,"")
D62: =IF(AND($C62="x",$A62<>""),$A62,"")
D63: =IF(AND($C63="x",$A63<>""),$A63,"")
D64: =IF(AND($C64="x",$A64<>""),$A64,"")
D65: =IF(AND($C65="x",$A65<>""),$A65,"")
D66: =IF(AND($C66="x",$A66<>""),$A66,"")
D67: =IF(AND($C67="x",$A67<>""),$A67,"")
D68: =IF(AND($C68="x",$A68<>""),$A68,"")
D69: =IF(AND($C69="x",$A69<>""),$A69,"")
... D80: =IF(AND($C80="x",$A80<>""),$A80,"")

Sheet Meta Ads doelgroep
A1: Windsor-export: Meta Ads doelgroep | C1: Status: Optioneel (anders live) · Ads → Meta doelgroepblok (aandelen)
A2: Connector | B2: facebook
A3: Account-id (uit Instellingen) | B3: =Instellingen!$B$11
A4: Taaknaam (Task name) | B4: ="Windsor - Sheets - Meta Ads doelgroep - "&Instellingen!$B$3
A5: Tabnaam (Sheet Name) | B5: ="Meta Ads - doelgroep - "&Instellingen!$B$3&" - windsor.ai" | C5: Herkenning in api/_sheetdata.js gaat op bron + niveau in deze naam; hou het voorstel aan.
A6: Columns to Match (rows to replace) | B6: date | C6: Voorstel; zoals bij de bestaande exports.
A7: Schedule | B7: Daily · 00:00 UTC · Target Cell A1 · Authentication: Google Account
A8: Query (gegenereerd — api_key blijft leeg) | B8: ="https://connectors.windsor.ai/"&$B$2&"?api_key="&IF(Instellingen!$B$4<>"","&date_preset="&Instellingen!$B$4,"")&"&fields="&_xlfn.TEXTJOIN(",",TRUE,$D$12:$D$80)&IF($B$3<>"","&select_accounts="&$B$3,"")&IF(Instellingen!$B$5<>"","&_field_headers="&Instellingen!$B$5,"")
A9: Aantal velden in de query | B9: =COUNTIF($C$12:$C$80,"x")
A11: Veld (Windsor-id) | B11: Gebruik in het dashboard | C11: Opnemen (x) | D11: → query
A12: date | B12: Datumkolom: 'Columns to Match' en periodefilter | C12: x | D12: =IF(AND($C12="x",$A12<>""),$A12,"")
A13: account_id | B13: Accountcontrole: alleen rijen van dit account tellen mee | C13: x | D13: =IF(AND($C13="x",$A13<>""),$A13,"")
A14: account_name | B14: Idem, leesbaar | C14: x | D14: =IF(AND($C14="x",$A14<>""),$A14,"")
A15: age | B15: Leeftijdsgroep (kop 'Age Range') | C15: x | D15: =IF(AND($C15="x",$A15<>""),$A15,"")
A16: gender | B16: Geslacht | C16: x | D16: =IF(AND($C16="x",$A16<>""),$A16,"")
A17: spend | B17: Kosten | C17: x | D17: =IF(AND($C17="x",$A17<>""),$A17,"")
A18: impressions | B18: Vertoningen | C18: x | D18: =IF(AND($C18="x",$A18<>""),$A18,"")
A19: clicks | B19: Kliks | C19: x | D19: =IF(AND($C19="x",$A19<>""),$A19,"")
A20: actions_add_to_cart | B20: Winkelmand (gewoon veld: omni weigert deze breakdown) | C20: x | D20: =IF(AND($C20="x",$A20<>""),$A20,"")
A21: actions_initiate_checkout | B21: Afrekenen | C21: x | D21: =IF(AND($C21="x",$A21<>""),$A21,"")
A22: actions_purchase | B22: Aankopen | C22: x | D22: =IF(AND($C22="x",$A22<>""),$A22,"")
A23: action_values_purchase | B23: Aankoopwaarde | C23: x | D23: =IF(AND($C23="x",$A23<>""),$A23,"")
A24: actions_lead | B24: Leads | C24: x | D24: =IF(AND($C24="x",$A24<>""),$A24,"")
A25: Eigen veld toevoegen: zet hieronder het Windsor-veld-id in kolom A en een x in kolom C (tot rij 80).
D26: =IF(AND($C26="x",$A26<>""),$A26,"")
D27: =IF(AND($C27="x",$A27<>""),$A27,"")
D28: =IF(AND($C28="x",$A28<>""),$A28,"")
D29: =IF(AND($C29="x",$A29<>""),$A29,"")
D30: =IF(AND($C30="x",$A30<>""),$A30,"")
D31: =IF(AND($C31="x",$A31<>""),$A31,"")
D32: =IF(AND($C32="x",$A32<>""),$A32,"")
D33: =IF(AND($C33="x",$A33<>""),$A33,"")
D34: =IF(AND($C34="x",$A34<>""),$A34,"")
D35: =IF(AND($C35="x",$A35<>""),$A35,"")
D36: =IF(AND($C36="x",$A36<>""),$A36,"")
D37: =IF(AND($C37="x",$A37<>""),$A37,"")
... D80: =IF(AND($C80="x",$A80<>""),$A80,"")

Sheet Meta Ads regio
A1: Windsor-export: Meta Ads regio | C1: Status: Optioneel (anders live) · Ads → Meta regio
A2: Connector | B2: facebook
A3: Account-id (uit Instellingen) | B3: =Instellingen!$B$11
A4: Taaknaam (Task name) | B4: ="Windsor - Sheets - Meta Ads regio - "&Instellingen!$B$3
A5: Tabnaam (Sheet Name) | B5: ="Meta Ads - regio - "&Instellingen!$B$3&" - windsor.ai" | C5: Herkenning in api/_sheetdata.js gaat op bron + niveau in deze naam; hou het voorstel aan.
A6: Columns to Match (rows to replace) | B6: date | C6: Voorstel; zoals bij de bestaande exports.
A7: Schedule | B7: Daily · 00:00 UTC · Target Cell A1 · Authentication: Google Account
A8: Query (gegenereerd — api_key blijft leeg) | B8: ="https://connectors.windsor.ai/"&$B$2&"?api_key="&IF(Instellingen!$B$4<>"","&date_preset="&Instellingen!$B$4,"")&"&fields="&_xlfn.TEXTJOIN(",",TRUE,$D$12:$D$80)&IF($B$3<>"","&select_accounts="&$B$3,"")&IF(Instellingen!$B$5<>"","&_field_headers="&Instellingen!$B$5,"")
A9: Aantal velden in de query | B9: =COUNTIF($C$12:$C$80,"x")
A11: Veld (Windsor-id) | B11: Gebruik in het dashboard | C11: Opnemen (x) | D11: → query
A12: date | B12: Datumkolom: 'Columns to Match' en periodefilter | C12: x | D12: =IF(AND($C12="x",$A12<>""),$A12,"")
A13: account_id | B13: Accountcontrole: alleen rijen van dit account tellen mee | C13: x | D13: =IF(AND($C13="x",$A13<>""),$A13,"")
A14: account_name | B14: Idem, leesbaar | C14: x | D14: =IF(AND($C14="x",$A14<>""),$A14,"")
A15: region | B15: Regio | C15: x | D15: =IF(AND($C15="x",$A15<>""),$A15,"")
A16: spend | B16: Kosten | C16: x | D16: =IF(AND($C16="x",$A16<>""),$A16,"")
A17: impressions | B17: Vertoningen | C17: x | D17: =IF(AND($C17="x",$A17<>""),$A17,"")
A18: clicks | B18: Kliks | C18: x | D18: =IF(AND($C18="x",$A18<>""),$A18,"")
A19: actions_purchase | B19: Aankopen (vaak leeg per regio) | C19: x | D19: =IF(AND($C19="x",$A19<>""),$A19,"")
A20: actions_lead | B20: Leads | C20: x | D20: =IF(AND($C20="x",$A20<>""),$A20,"")
A21: Eigen veld toevoegen: zet hieronder het Windsor-veld-id in kolom A en een x in kolom C (tot rij 80).
D22: =IF(AND($C22="x",$A22<>""),$A22,"")
D23: =IF(AND($C23="x",$A23<>""),$A23,"")
D24: =IF(AND($C24="x",$A24<>""),$A24,"")
D25: =IF(AND($C25="x",$A25<>""),$A25,"")
D26: =IF(AND($C26="x",$A26<>""),$A26,"")
D27: =IF(AND($C27="x",$A27<>""),$A27,"")
D28: =IF(AND($C28="x",$A28<>""),$A28,"")
D29: =IF(AND($C29="x",$A29<>""),$A29,"")
D30: =IF(AND($C30="x",$A30<>""),$A30,"")
D31: =IF(AND($C31="x",$A31<>""),$A31,"")
D32: =IF(AND($C32="x",$A32<>""),$A32,"")
D33: =IF(AND($C33="x",$A33<>""),$A33,"")
... D80: =IF(AND($C80="x",$A80<>""),$A80,"")

Sheet Meta Ads asset titel
A1: Windsor-export: Meta Ads asset titel | C1: Status: Optioneel (anders live) · Ads → Meta creatieve varianten
A2: Connector | B2: facebook
A3: Account-id (uit Instellingen) | B3: =Instellingen!$B$11
A4: Taaknaam (Task name) | B4: ="Windsor - Sheets - Meta Ads asset titel - "&Instellingen!$B$3
A5: Tabnaam (Sheet Name) | B5: ="Meta Ads - asset titel - "&Instellingen!$B$3&" - windsor.ai" | C5: Herkenning in api/_sheetdata.js gaat op bron + niveau in deze naam; hou het voorstel aan.
A6: Columns to Match (rows to replace) | B6: date | C6: Voorstel; zoals bij de bestaande exports.
A7: Schedule | B7: Daily · 00:00 UTC · Target Cell A1 · Authentication: Google Account
A8: Query (gegenereerd — api_key blijft leeg) | B8: ="https://connectors.windsor.ai/"&$B$2&"?api_key="&IF(Instellingen!$B$4<>"","&date_preset="&Instellingen!$B$4,"")&"&fields="&_xlfn.TEXTJOIN(",",TRUE,$D$12:$D$80)&IF($B$3<>"","&select_accounts="&$B$3,"")&IF(Instellingen!$B$5<>"","&_field_headers="&Instellingen!$B$5,"")
A9: Aantal velden in de query | B9: =COUNTIF($C$12:$C$80,"x")
A11: Veld (Windsor-id) | B11: Gebruik in het dashboard | C11: Opnemen (x) | D11: → query
A12: date | B12: Datumkolom: 'Columns to Match' en periodefilter | C12: x | D12: =IF(AND($C12="x",$A12<>""),$A12,"")
A13: account_id | B13: Accountcontrole: alleen rijen van dit account tellen mee | C13: x | D13: =IF(AND($C13="x",$A13<>""),$A13,"")
A14: account_name | B14: Idem, leesbaar | C14: x | D14: =IF(AND($C14="x",$A14<>""),$A14,"")
A15: ad_id | B15: Advertentie | C15: x | D15: =IF(AND($C15="x",$A15<>""),$A15,"")
A16: title_asset_text | B16: Titelvariant — één asset-breakdown per export | C16: x | D16: =IF(AND($C16="x",$A16<>""),$A16,"")
A17: impressions | B17: Vertoningen | C17: x | D17: =IF(AND($C17="x",$A17<>""),$A17,"")
A18: clicks | B18: Kliks | C18: x | D18: =IF(AND($C18="x",$A18<>""),$A18,"")
A19: spend | B19: Kosten | C19: x | D19: =IF(AND($C19="x",$A19<>""),$A19,"")
A20: actions_purchase | B20: Aankopen (Meta kan dit weigeren naast de breakdown; dan weglaten) | C20: x | D20: =IF(AND($C20="x",$A20<>""),$A20,"")
A21: actions_lead | B21: Leads (idem) | C21: x | D21: =IF(AND($C21="x",$A21<>""),$A21,"")
A22: Eigen veld toevoegen: zet hieronder het Windsor-veld-id in kolom A en een x in kolom C (tot rij 80).
D23: =IF(AND($C23="x",$A23<>""),$A23,"")
D24: =IF(AND($C24="x",$A24<>""),$A24,"")
D25: =IF(AND($C25="x",$A25<>""),$A25,"")
D26: =IF(AND($C26="x",$A26<>""),$A26,"")
D27: =IF(AND($C27="x",$A27<>""),$A27,"")
D28: =IF(AND($C28="x",$A28<>""),$A28,"")
D29: =IF(AND($C29="x",$A29<>""),$A29,"")
D30: =IF(AND($C30="x",$A30<>""),$A30,"")
D31: =IF(AND($C31="x",$A31<>""),$A31,"")
D32: =IF(AND($C32="x",$A32<>""),$A32,"")
D33: =IF(AND($C33="x",$A33<>""),$A33,"")
D34: =IF(AND($C34="x",$A34<>""),$A34,"")
... D80: =IF(AND($C80="x",$A80<>""),$A80,"")

Sheet Meta Ads asset body
A1: Windsor-export: Meta Ads asset body | C1: Status: Optioneel (anders live) · Ads → Meta creatieve varianten
A2: Connector | B2: facebook
A3: Account-id (uit Instellingen) | B3: =Instellingen!$B$11
A4: Taaknaam (Task name) | B4: ="Windsor - Sheets - Meta Ads asset body - "&Instellingen!$B$3
A5: Tabnaam (Sheet Name) | B5: ="Meta Ads - asset body - "&Instellingen!$B$3&" - windsor.ai" | C5: Herkenning in api/_sheetdata.js gaat op bron + niveau in deze naam; hou het voorstel aan.
A6: Columns to Match (rows to replace) | B6: date | C6: Voorstel; zoals bij de bestaande exports.
A7: Schedule | B7: Daily · 00:00 UTC · Target Cell A1 · Authentication: Google Account
A8: Query (gegenereerd — api_key blijft leeg) | B8: ="https://connectors.windsor.ai/"&$B$2&"?api_key="&IF(Instellingen!$B$4<>"","&date_preset="&Instellingen!$B$4,"")&"&fields="&_xlfn.TEXTJOIN(",",TRUE,$D$12:$D$80)&IF($B$3<>"","&select_accounts="&$B$3,"")&IF(Instellingen!$B$5<>"","&_field_headers="&Instellingen!$B$5,"")
A9: Aantal velden in de query | B9: =COUNTIF($C$12:$C$80,"x")
A11: Veld (Windsor-id) | B11: Gebruik in het dashboard | C11: Opnemen (x) | D11: → query
A12: date | B12: Datumkolom: 'Columns to Match' en periodefilter | C12: x | D12: =IF(AND($C12="x",$A12<>""),$A12,"")
A13: account_id | B13: Accountcontrole: alleen rijen van dit account tellen mee | C13: x | D13: =IF(AND($C13="x",$A13<>""),$A13,"")
A14: account_name | B14: Idem, leesbaar | C14: x | D14: =IF(AND($C14="x",$A14<>""),$A14,"")
A15: ad_id | B15: Advertentie | C15: x | D15: =IF(AND($C15="x",$A15<>""),$A15,"")
A16: body_asset_text | B16: Tekstvariant — één asset-breakdown per export | C16: x | D16: =IF(AND($C16="x",$A16<>""),$A16,"")
A17: impressions | B17: Vertoningen | C17: x | D17: =IF(AND($C17="x",$A17<>""),$A17,"")
A18: clicks | B18: Kliks | C18: x | D18: =IF(AND($C18="x",$A18<>""),$A18,"")
A19: spend | B19: Kosten | C19: x | D19: =IF(AND($C19="x",$A19<>""),$A19,"")
A20: actions_purchase | B20: Aankopen (Meta kan dit weigeren naast de breakdown; dan weglaten) | C20: x | D20: =IF(AND($C20="x",$A20<>""),$A20,"")
A21: actions_lead | B21: Leads (idem) | C21: x | D21: =IF(AND($C21="x",$A21<>""),$A21,"")
A22: Eigen veld toevoegen: zet hieronder het Windsor-veld-id in kolom A en een x in kolom C (tot rij 80).
D23: =IF(AND($C23="x",$A23<>""),$A23,"")
D24: =IF(AND($C24="x",$A24<>""),$A24,"")
D25: =IF(AND($C25="x",$A25<>""),$A25,"")
D26: =IF(AND($C26="x",$A26<>""),$A26,"")
D27: =IF(AND($C27="x",$A27<>""),$A27,"")
D28: =IF(AND($C28="x",$A28<>""),$A28,"")
D29: =IF(AND($C29="x",$A29<>""),$A29,"")
D30: =IF(AND($C30="x",$A30<>""),$A30,"")
D31: =IF(AND($C31="x",$A31<>""),$A31,"")
D32: =IF(AND($C32="x",$A32<>""),$A32,"")
D33: =IF(AND($C33="x",$A33<>""),$A33,"")
D34: =IF(AND($C34="x",$A34<>""),$A34,"")
... D80: =IF(AND($C80="x",$A80<>""),$A80,"")

Sheet Meta Ads asset CTA
A1: Windsor-export: Meta Ads asset CTA | C1: Status: Optioneel (anders live) · Ads → Meta creatieve varianten
A2: Connector | B2: facebook
A3: Account-id (uit Instellingen) | B3: =Instellingen!$B$11
A4: Taaknaam (Task name) | B4: ="Windsor - Sheets - Meta Ads asset CTA - "&Instellingen!$B$3
A5: Tabnaam (Sheet Name) | B5: ="Meta Ads - asset CTA - "&Instellingen!$B$3&" - windsor.ai" | C5: Herkenning in api/_sheetdata.js gaat op bron + niveau in deze naam; hou het voorstel aan.
A6: Columns to Match (rows to replace) | B6: date | C6: Voorstel; zoals bij de bestaande exports.
A7: Schedule | B7: Daily · 00:00 UTC · Target Cell A1 · Authentication: Google Account
A8: Query (gegenereerd — api_key blijft leeg) | B8: ="https://connectors.windsor.ai/"&$B$2&"?api_key="&IF(Instellingen!$B$4<>"","&date_preset="&Instellingen!$B$4,"")&"&fields="&_xlfn.TEXTJOIN(",",TRUE,$D$12:$D$80)&IF($B$3<>"","&select_accounts="&$B$3,"")&IF(Instellingen!$B$5<>"","&_field_headers="&Instellingen!$B$5,"")
A9: Aantal velden in de query | B9: =COUNTIF($C$12:$C$80,"x")
A11: Veld (Windsor-id) | B11: Gebruik in het dashboard | C11: Opnemen (x) | D11: → query
A12: date | B12: Datumkolom: 'Columns to Match' en periodefilter | C12: x | D12: =IF(AND($C12="x",$A12<>""),$A12,"")
A13: account_id | B13: Accountcontrole: alleen rijen van dit account tellen mee | C13: x | D13: =IF(AND($C13="x",$A13<>""),$A13,"")
A14: account_name | B14: Idem, leesbaar | C14: x | D14: =IF(AND($C14="x",$A14<>""),$A14,"")
A15: ad_id | B15: Advertentie | C15: x | D15: =IF(AND($C15="x",$A15<>""),$A15,"")
A16: call_to_action_asset_name | B16: CTA-variant — één asset-breakdown per export | C16: x | D16: =IF(AND($C16="x",$A16<>""),$A16,"")
A17: impressions | B17: Vertoningen | C17: x | D17: =IF(AND($C17="x",$A17<>""),$A17,"")
A18: clicks | B18: Kliks | C18: x | D18: =IF(AND($C18="x",$A18<>""),$A18,"")
A19: spend | B19: Kosten | C19: x | D19: =IF(AND($C19="x",$A19<>""),$A19,"")
A20: actions_purchase | B20: Aankopen (Meta kan dit weigeren naast de breakdown; dan weglaten) | C20: x | D20: =IF(AND($C20="x",$A20<>""),$A20,"")
A21: actions_lead | B21: Leads (idem) | C21: x | D21: =IF(AND($C21="x",$A21<>""),$A21,"")
A22: Eigen veld toevoegen: zet hieronder het Windsor-veld-id in kolom A en een x in kolom C (tot rij 80).
D23: =IF(AND($C23="x",$A23<>""),$A23,"")
D24: =IF(AND($C24="x",$A24<>""),$A24,"")
D25: =IF(AND($C25="x",$A25<>""),$A25,"")
D26: =IF(AND($C26="x",$A26<>""),$A26,"")
D27: =IF(AND($C27="x",$A27<>""),$A27,"")
D28: =IF(AND($C28="x",$A28<>""),$A28,"")
D29: =IF(AND($C29="x",$A29<>""),$A29,"")
D30: =IF(AND($C30="x",$A30<>""),$A30,"")
D31: =IF(AND($C31="x",$A31<>""),$A31,"")
D32: =IF(AND($C32="x",$A32<>""),$A32,"")
D33: =IF(AND($C33="x",$A33<>""),$A33,"")
D34: =IF(AND($C34="x",$A34<>""),$A34,"")
... D80: =IF(AND($C80="x",$A80<>""),$A80,"")

Sheet Meta Ads asset image
A1: Windsor-export: Meta Ads asset image | C1: Status: Optioneel (anders live) · Ads → Meta creatieve varianten
A2: Connector | B2: facebook
A3: Account-id (uit Instellingen) | B3: =Instellingen!$B$11
A4: Taaknaam (Task name) | B4: ="Windsor - Sheets - Meta Ads asset image - "&Instellingen!$B$3
A5: Tabnaam (Sheet Name) | B5: ="Meta Ads - asset image - "&Instellingen!$B$3&" - windsor.ai" | C5: Herkenning in api/_sheetdata.js gaat op bron + niveau in deze naam; hou het voorstel aan.
A6: Columns to Match (rows to replace) | B6: date | C6: Voorstel; zoals bij de bestaande exports.
A7: Schedule | B7: Daily · 00:00 UTC · Target Cell A1 · Authentication: Google Account
A8: Query (gegenereerd — api_key blijft leeg) | B8: ="https://connectors.windsor.ai/"&$B$2&"?api_key="&IF(Instellingen!$B$4<>"","&date_preset="&Instellingen!$B$4,"")&"&fields="&_xlfn.TEXTJOIN(",",TRUE,$D$12:$D$80)&IF($B$3<>"","&select_accounts="&$B$3,"")&IF(Instellingen!$B$5<>"","&_field_headers="&Instellingen!$B$5,"")
A9: Aantal velden in de query | B9: =COUNTIF($C$12:$C$80,"x")
A11: Veld (Windsor-id) | B11: Gebruik in het dashboard | C11: Opnemen (x) | D11: → query
A12: date | B12: Datumkolom: 'Columns to Match' en periodefilter | C12: x | D12: =IF(AND($C12="x",$A12<>""),$A12,"")
A13: account_id | B13: Accountcontrole: alleen rijen van dit account tellen mee | C13: x | D13: =IF(AND($C13="x",$A13<>""),$A13,"")
A14: account_name | B14: Idem, leesbaar | C14: x | D14: =IF(AND($C14="x",$A14<>""),$A14,"")
A15: ad_id | B15: Advertentie | C15: x | D15: =IF(AND($C15="x",$A15<>""),$A15,"")
A16: image_asset_url | B16: Beeldvariant — één asset-breakdown per export | C16: x | D16: =IF(AND($C16="x",$A16<>""),$A16,"")
A17: impressions | B17: Vertoningen | C17: x | D17: =IF(AND($C17="x",$A17<>""),$A17,"")
A18: clicks | B18: Kliks | C18: x | D18: =IF(AND($C18="x",$A18<>""),$A18,"")
A19: spend | B19: Kosten | C19: x | D19: =IF(AND($C19="x",$A19<>""),$A19,"")
A20: actions_purchase | B20: Aankopen (Meta kan dit weigeren naast de breakdown; dan weglaten) | C20: x | D20: =IF(AND($C20="x",$A20<>""),$A20,"")
A21: actions_lead | B21: Leads (idem) | C21: x | D21: =IF(AND($C21="x",$A21<>""),$A21,"")
A22: Eigen veld toevoegen: zet hieronder het Windsor-veld-id in kolom A en een x in kolom C (tot rij 80).
D23: =IF(AND($C23="x",$A23<>""),$A23,"")
D24: =IF(AND($C24="x",$A24<>""),$A24,"")
D25: =IF(AND($C25="x",$A25<>""),$A25,"")
D26: =IF(AND($C26="x",$A26<>""),$A26,"")
D27: =IF(AND($C27="x",$A27<>""),$A27,"")
D28: =IF(AND($C28="x",$A28<>""),$A28,"")
D29: =IF(AND($C29="x",$A29<>""),$A29,"")
D30: =IF(AND($C30="x",$A30<>""),$A30,"")
D31: =IF(AND($C31="x",$A31<>""),$A31,"")
D32: =IF(AND($C32="x",$A32<>""),$A32,"")
D33: =IF(AND($C33="x",$A33<>""),$A33,"")
D34: =IF(AND($C34="x",$A34<>""),$A34,"")
... D80: =IF(AND($C80="x",$A80<>""),$A80,"")

Sheet Meta Ads asset video
A1: Windsor-export: Meta Ads asset video | C1: Status: Optioneel (anders live) · Ads → Meta creatieve varianten
A2: Connector | B2: facebook
A3: Account-id (uit Instellingen) | B3: =Instellingen!$B$11
A4: Taaknaam (Task name) | B4: ="Windsor - Sheets - Meta Ads asset video - "&Instellingen!$B$3
A5: Tabnaam (Sheet Name) | B5: ="Meta Ads - asset video - "&Instellingen!$B$3&" - windsor.ai" | C5: Herkenning in api/_sheetdata.js gaat op bron + niveau in deze naam; hou het voorstel aan.
A6: Columns to Match (rows to replace) | B6: date | C6: Voorstel; zoals bij de bestaande exports.
A7: Schedule | B7: Daily · 00:00 UTC · Target Cell A1 · Authentication: Google Account
A8: Query (gegenereerd — api_key blijft leeg) | B8: ="https://connectors.windsor.ai/"&$B$2&"?api_key="&IF(Instellingen!$B$4<>"","&date_preset="&Instellingen!$B$4,"")&"&fields="&_xlfn.TEXTJOIN(",",TRUE,$D$12:$D$80)&IF($B$3<>"","&select_accounts="&$B$3,"")&IF(Instellingen!$B$5<>"","&_field_headers="&Instellingen!$B$5,"")
A9: Aantal velden in de query | B9: =COUNTIF($C$12:$C$80,"x")
A11: Veld (Windsor-id) | B11: Gebruik in het dashboard | C11: Opnemen (x) | D11: → query
A12: date | B12: Datumkolom: 'Columns to Match' en periodefilter | C12: x | D12: =IF(AND($C12="x",$A12<>""),$A12,"")
A13: account_id | B13: Accountcontrole: alleen rijen van dit account tellen mee | C13: x | D13: =IF(AND($C13="x",$A13<>""),$A13,"")
A14: account_name | B14: Idem, leesbaar | C14: x | D14: =IF(AND($C14="x",$A14<>""),$A14,"")
A15: ad_id | B15: Advertentie | C15: x | D15: =IF(AND($C15="x",$A15<>""),$A15,"")
A16: video_asset_video_name | B16: Videovariant — één asset-breakdown per export | C16: x | D16: =IF(AND($C16="x",$A16<>""),$A16,"")
A17: impressions | B17: Vertoningen | C17: x | D17: =IF(AND($C17="x",$A17<>""),$A17,"")
A18: clicks | B18: Kliks | C18: x | D18: =IF(AND($C18="x",$A18<>""),$A18,"")
A19: spend | B19: Kosten | C19: x | D19: =IF(AND($C19="x",$A19<>""),$A19,"")
A20: actions_purchase | B20: Aankopen (Meta kan dit weigeren naast de breakdown; dan weglaten) | C20: x | D20: =IF(AND($C20="x",$A20<>""),$A20,"")
A21: actions_lead | B21: Leads (idem) | C21: x | D21: =IF(AND($C21="x",$A21<>""),$A21,"")
A22: Eigen veld toevoegen: zet hieronder het Windsor-veld-id in kolom A en een x in kolom C (tot rij 80).
D23: =IF(AND($C23="x",$A23<>""),$A23,"")
D24: =IF(AND($C24="x",$A24<>""),$A24,"")
D25: =IF(AND($C25="x",$A25<>""),$A25,"")
D26: =IF(AND($C26="x",$A26<>""),$A26,"")
D27: =IF(AND($C27="x",$A27<>""),$A27,"")
D28: =IF(AND($C28="x",$A28<>""),$A28,"")
D29: =IF(AND($C29="x",$A29<>""),$A29,"")
D30: =IF(AND($C30="x",$A30<>""),$A30,"")
D31: =IF(AND($C31="x",$A31<>""),$A31,"")
D32: =IF(AND($C32="x",$A32<>""),$A32,"")
D33: =IF(AND($C33="x",$A33<>""),$A33,"")
D34: =IF(AND($C34="x",$A34<>""),$A34,"")
... D80: =IF(AND($C80="x",$A80<>""),$A80,"")

Sheet GA4 dag
A1: Windsor-export: GA4 dag | C1: Status: Aanbevolen · Website (totalen, dagreeks) + ROAS (GA4-omzet) + Doelen
A2: Connector | B2: googleanalytics4
A3: Account-id (uit Instellingen) | B3: =Instellingen!$B$12
A4: Taaknaam (Task name) | B4: ="Windsor - Sheets - GA4 dag - "&Instellingen!$B$3
A5: Tabnaam (Sheet Name) | B5: ="Google Analytics 4 - dag - "&Instellingen!$B$3&" - windsor.ai" | C5: Herkenning in api/_sheetdata.js gaat op bron + niveau in deze naam; hou het voorstel aan.
A6: Columns to Match (rows to replace) | B6: date | C6: Voorstel; zoals bij de bestaande exports.
A7: Schedule | B7: Daily · 00:00 UTC · Target Cell A1 · Authentication: Google Account
A8: Query (gegenereerd — api_key blijft leeg) | B8: ="https://connectors.windsor.ai/"&$B$2&"?api_key="&IF(Instellingen!$B$4<>"","&date_preset="&Instellingen!$B$4,"")&"&fields="&_xlfn.TEXTJOIN(",",TRUE,$D$12:$D$80)&IF($B$3<>"","&select_accounts="&$B$3,"")&IF(Instellingen!$B$5<>"","&_field_headers="&Instellingen!$B$5,"")
A9: Aantal velden in de query | B9: =COUNTIF($C$12:$C$80,"x")
A11: Veld (Windsor-id) | B11: Gebruik in het dashboard | C11: Opnemen (x) | D11: → query
A12: date | B12: Datumkolom: 'Columns to Match' en periodefilter | C12: x | D12: =IF(AND($C12="x",$A12<>""),$A12,"")
A13: account_id | B13: Accountcontrole: alleen rijen van dit account tellen mee | C13: x | D13: =IF(AND($C13="x",$A13<>""),$A13,"")
A14: account_name | B14: Idem, leesbaar | C14: x | D14: =IF(AND($C14="x",$A14<>""),$A14,"")
A15: sessions | B15: Sessies | C15: x | D15: =IF(AND($C15="x",$A15<>""),$A15,"")
A16: totalusers | B16: Gebruikers (kop 'Total users'; niet optelbaar over dagen → UI toont nieuwe gebruikers) | C16: x | D16: =IF(AND($C16="x",$A16<>""),$A16,"")
A17: newusers | B17: Nieuwe gebruikers | C17: x | D17: =IF(AND($C17="x",$A17<>""),$A17,"")
A18: engaged_sessions | B18: Betrokken sessies | C18: x | D18: =IF(AND($C18="x",$A18<>""),$A18,"")
A19: screen_page_views | B19: Weergaven (kop 'Views') | C19: x | D19: =IF(AND($C19="x",$A19<>""),$A19,"")
A20: user_engagement_duration | B20: Betrokkenheidsduur | C20: x | D20: =IF(AND($C20="x",$A20<>""),$A20,"")
A21: conversions | B21: Key events, alle samen | C21: x | D21: =IF(AND($C21="x",$A21<>""),$A21,"")
A22: purchase_revenue | B22: Omzet (ook ROAS-tab) | C22: x | D22: =IF(AND($C22="x",$A22<>""),$A22,"")
A23: transactions | B23: Transacties | C23: x | D23: =IF(AND($C23="x",$A23<>""),$A23,"")
A24: =IF(Instellingen!$B$6<>"","conversions_"&Instellingen!$B$6,"") | B24: Hoofddoel per klant (Config 'Conversiedoel'); kop wordt 'Key event count for <event>' | C24: x | D24: =IF(AND($C24="x",$A24<>""),$A24,"")
A25: Eigen veld toevoegen: zet hieronder het Windsor-veld-id in kolom A en een x in kolom C (tot rij 80).
D26: =IF(AND($C26="x",$A26<>""),$A26,"")
D27: =IF(AND($C27="x",$A27<>""),$A27,"")
D28: =IF(AND($C28="x",$A28<>""),$A28,"")
D29: =IF(AND($C29="x",$A29<>""),$A29,"")
D30: =IF(AND($C30="x",$A30<>""),$A30,"")
D31: =IF(AND($C31="x",$A31<>""),$A31,"")
D32: =IF(AND($C32="x",$A32<>""),$A32,"")
D33: =IF(AND($C33="x",$A33<>""),$A33,"")
D34: =IF(AND($C34="x",$A34<>""),$A34,"")
D35: =IF(AND($C35="x",$A35<>""),$A35,"")
D36: =IF(AND($C36="x",$A36<>""),$A36,"")
D37: =IF(AND($C37="x",$A37<>""),$A37,"")
... D80: =IF(AND($C80="x",$A80<>""),$A80,"")

Sheet GA4 kanaal
A1: Windsor-export: GA4 kanaal | C1: Status: Aanbevolen · Website (donut, bronnen) + ROAS-kanaalsplitsing + AI-verkeer
A2: Connector | B2: googleanalytics4
A3: Account-id (uit Instellingen) | B3: =Instellingen!$B$12
A4: Taaknaam (Task name) | B4: ="Windsor - Sheets - GA4 kanaal - "&Instellingen!$B$3
A5: Tabnaam (Sheet Name) | B5: ="Google Analytics 4 - kanaal - "&Instellingen!$B$3&" - windsor.ai" | C5: Herkenning in api/_sheetdata.js gaat op bron + niveau in deze naam; hou het voorstel aan.
A6: Columns to Match (rows to replace) | B6: date | C6: Voorstel; zoals bij de bestaande exports.
A7: Schedule | B7: Daily · 00:00 UTC · Target Cell A1 · Authentication: Google Account
A8: Query (gegenereerd — api_key blijft leeg) | B8: ="https://connectors.windsor.ai/"&$B$2&"?api_key="&IF(Instellingen!$B$4<>"","&date_preset="&Instellingen!$B$4,"")&"&fields="&_xlfn.TEXTJOIN(",",TRUE,$D$12:$D$80)&IF($B$3<>"","&select_accounts="&$B$3,"")&IF(Instellingen!$B$5<>"","&_field_headers="&Instellingen!$B$5,"")
A9: Aantal velden in de query | B9: =COUNTIF($C$12:$C$80,"x")
A11: Veld (Windsor-id) | B11: Gebruik in het dashboard | C11: Opnemen (x) | D11: → query
A12: date | B12: Datumkolom: 'Columns to Match' en periodefilter | C12: x | D12: =IF(AND($C12="x",$A12<>""),$A12,"")
A13: account_id | B13: Accountcontrole: alleen rijen van dit account tellen mee | C13: x | D13: =IF(AND($C13="x",$A13<>""),$A13,"")
A14: account_name | B14: Idem, leesbaar | C14: x | D14: =IF(AND($C14="x",$A14<>""),$A14,"")
A15: session_default_channel_group | B15: Kanaalgroep (donut) | C15: x | D15: =IF(AND($C15="x",$A15<>""),$A15,"")
A16: session_source_medium | B16: Bron/medium (Bronnen-tabel én ROAS-kanaalsplitsing én AI-verkeer) | C16: x | D16: =IF(AND($C16="x",$A16<>""),$A16,"")
A17: sessions | B17: Sessies | C17: x | D17: =IF(AND($C17="x",$A17<>""),$A17,"")
A18: engaged_sessions | B18: Betrokken sessies | C18: x | D18: =IF(AND($C18="x",$A18<>""),$A18,"")
A19: newusers | B19: Nieuwe gebruikers | C19: x | D19: =IF(AND($C19="x",$A19<>""),$A19,"")
A20: conversions | B20: Key events | C20: x | D20: =IF(AND($C20="x",$A20<>""),$A20,"")
A21: purchase_revenue | B21: Omzet | C21: x | D21: =IF(AND($C21="x",$A21<>""),$A21,"")
A22: transactions | B22: Transacties | C22: x | D22: =IF(AND($C22="x",$A22<>""),$A22,"")
A23: =IF(Instellingen!$B$6<>"","conversions_"&Instellingen!$B$6,"") | B23: Hoofddoel per klant (Config 'Conversiedoel'); kop wordt 'Key event count for <event>' | C23: x | D23: =IF(AND($C23="x",$A23<>""),$A23,"")
A24: Eigen veld toevoegen: zet hieronder het Windsor-veld-id in kolom A en een x in kolom C (tot rij 80).
D25: =IF(AND($C25="x",$A25<>""),$A25,"")
D26: =IF(AND($C26="x",$A26<>""),$A26,"")
D27: =IF(AND($C27="x",$A27<>""),$A27,"")
D28: =IF(AND($C28="x",$A28<>""),$A28,"")
D29: =IF(AND($C29="x",$A29<>""),$A29,"")
D30: =IF(AND($C30="x",$A30<>""),$A30,"")
D31: =IF(AND($C31="x",$A31<>""),$A31,"")
D32: =IF(AND($C32="x",$A32<>""),$A32,"")
D33: =IF(AND($C33="x",$A33<>""),$A33,"")
D34: =IF(AND($C34="x",$A34<>""),$A34,"")
D35: =IF(AND($C35="x",$A35<>""),$A35,"")
D36: =IF(AND($C36="x",$A36<>""),$A36,"")
... D80: =IF(AND($C80="x",$A80<>""),$A80,"")

Sheet GA4 landing
A1: Windsor-export: GA4 landing | C1: Status: Aanbevolen · Website → landingspagina's
A2: Connector | B2: googleanalytics4
A3: Account-id (uit Instellingen) | B3: =Instellingen!$B$12
A4: Taaknaam (Task name) | B4: ="Windsor - Sheets - GA4 landing - "&Instellingen!$B$3
A5: Tabnaam (Sheet Name) | B5: ="Google Analytics 4 - landing - "&Instellingen!$B$3&" - windsor.ai" | C5: Herkenning in api/_sheetdata.js gaat op bron + niveau in deze naam; hou het voorstel aan.
A6: Columns to Match (rows to replace) | B6: date | C6: Voorstel; zoals bij de bestaande exports.
A7: Schedule | B7: Daily · 00:00 UTC · Target Cell A1 · Authentication: Google Account
A8: Query (gegenereerd — api_key blijft leeg) | B8: ="https://connectors.windsor.ai/"&$B$2&"?api_key="&IF(Instellingen!$B$4<>"","&date_preset="&Instellingen!$B$4,"")&"&fields="&_xlfn.TEXTJOIN(",",TRUE,$D$12:$D$80)&IF($B$3<>"","&select_accounts="&$B$3,"")&IF(Instellingen!$B$5<>"","&_field_headers="&Instellingen!$B$5,"")
A9: Aantal velden in de query | B9: =COUNTIF($C$12:$C$80,"x")
A11: Veld (Windsor-id) | B11: Gebruik in het dashboard | C11: Opnemen (x) | D11: → query
A12: date | B12: Datumkolom: 'Columns to Match' en periodefilter | C12: x | D12: =IF(AND($C12="x",$A12<>""),$A12,"")
A13: account_id | B13: Accountcontrole: alleen rijen van dit account tellen mee | C13: x | D13: =IF(AND($C13="x",$A13<>""),$A13,"")
A14: account_name | B14: Idem, leesbaar | C14: x | D14: =IF(AND($C14="x",$A14<>""),$A14,"")
A15: landing_page | B15: Landingspagina | C15: x | D15: =IF(AND($C15="x",$A15<>""),$A15,"")
A16: sessions | B16: Sessies | C16: x | D16: =IF(AND($C16="x",$A16<>""),$A16,"")
A17: engaged_sessions | B17: Betrokken sessies | C17: x | D17: =IF(AND($C17="x",$A17<>""),$A17,"")
A18: conversions | B18: Key events (per sessie, kan > 1) | C18: x | D18: =IF(AND($C18="x",$A18<>""),$A18,"")
A19: purchase_revenue | B19: Omzet | C19: x | D19: =IF(AND($C19="x",$A19<>""),$A19,"")
A20: =IF(Instellingen!$B$6<>"","conversions_"&Instellingen!$B$6,"") | B20: Hoofddoel per klant (Config 'Conversiedoel'); kop wordt 'Key event count for <event>' | C20: x | D20: =IF(AND($C20="x",$A20<>""),$A20,"")
A21: Eigen veld toevoegen: zet hieronder het Windsor-veld-id in kolom A en een x in kolom C (tot rij 80).
D22: =IF(AND($C22="x",$A22<>""),$A22,"")
D23: =IF(AND($C23="x",$A23<>""),$A23,"")
D24: =IF(AND($C24="x",$A24<>""),$A24,"")
D25: =IF(AND($C25="x",$A25<>""),$A25,"")
D26: =IF(AND($C26="x",$A26<>""),$A26,"")
D27: =IF(AND($C27="x",$A27<>""),$A27,"")
D28: =IF(AND($C28="x",$A28<>""),$A28,"")
D29: =IF(AND($C29="x",$A29<>""),$A29,"")
D30: =IF(AND($C30="x",$A30<>""),$A30,"")
D31: =IF(AND($C31="x",$A31<>""),$A31,"")
D32: =IF(AND($C32="x",$A32<>""),$A32,"")
D33: =IF(AND($C33="x",$A33<>""),$A33,"")
... D80: =IF(AND($C80="x",$A80<>""),$A80,"")

Sheet GA4 doelgroep
A1: Windsor-export: GA4 doelgroep | C1: Status: Alleen klanten zonder Windsor-sleutel · Website → Doelgroep (dashboard haalt dit normaal live)
A2: Connector | B2: googleanalytics4
A3: Account-id (uit Instellingen) | B3: =Instellingen!$B$12
A4: Taaknaam (Task name) | B4: ="Windsor - Sheets - GA4 doelgroep - "&Instellingen!$B$3
A5: Tabnaam (Sheet Name) | B5: ="Google Analytics 4 - doelgroep - "&Instellingen!$B$3&" - windsor.ai" | C5: Herkenning in api/_sheetdata.js gaat op bron + niveau in deze naam; hou het voorstel aan.
A6: Columns to Match (rows to replace) | B6: date | C6: Voorstel; zoals bij de bestaande exports.
A7: Schedule | B7: Daily · 00:00 UTC · Target Cell A1 · Authentication: Google Account
A8: Query (gegenereerd — api_key blijft leeg) | B8: ="https://connectors.windsor.ai/"&$B$2&"?api_key="&IF(Instellingen!$B$4<>"","&date_preset="&Instellingen!$B$4,"")&"&fields="&_xlfn.TEXTJOIN(",",TRUE,$D$12:$D$80)&IF($B$3<>"","&select_accounts="&$B$3,"")&IF(Instellingen!$B$5<>"","&_field_headers="&Instellingen!$B$5,"")
A9: Aantal velden in de query | B9: =COUNTIF($C$12:$C$80,"x")
A11: Veld (Windsor-id) | B11: Gebruik in het dashboard | C11: Opnemen (x) | D11: → query
A12: date | B12: Datumkolom: 'Columns to Match' en periodefilter | C12: x | D12: =IF(AND($C12="x",$A12<>""),$A12,"")
A13: account_id | B13: Accountcontrole: alleen rijen van dit account tellen mee | C13: x | D13: =IF(AND($C13="x",$A13<>""),$A13,"")
A14: account_name | B14: Idem, leesbaar | C14: x | D14: =IF(AND($C14="x",$A14<>""),$A14,"")
A15: age | B15: Leeftijd (Google Signals vereist) | C15: x | D15: =IF(AND($C15="x",$A15<>""),$A15,"")
A16: gender | B16: Geslacht | C16: x | D16: =IF(AND($C16="x",$A16<>""),$A16,"")
A17: session_default_channel_group | B17: Kanaalgroep | C17: x | D17: =IF(AND($C17="x",$A17<>""),$A17,"")
A18: sessions | B18: Sessies | C18: x | D18: =IF(AND($C18="x",$A18<>""),$A18,"")
A19: engaged_sessions | B19: Betrokken sessies | C19: x | D19: =IF(AND($C19="x",$A19<>""),$A19,"")
A20: newusers | B20: Nieuwe gebruikers | C20: x | D20: =IF(AND($C20="x",$A20<>""),$A20,"")
A21: conversions | B21: Key events | C21: x | D21: =IF(AND($C21="x",$A21<>""),$A21,"")
A22: purchase_revenue | B22: Omzet | C22: x | D22: =IF(AND($C22="x",$A22<>""),$A22,"")
A23: transactions | B23: Transacties | C23: x | D23: =IF(AND($C23="x",$A23<>""),$A23,"")
A24: =IF(Instellingen!$B$6<>"","conversions_"&Instellingen!$B$6,"") | B24: Hoofddoel per klant (Config 'Conversiedoel'); kop wordt 'Key event count for <event>' | C24: x | D24: =IF(AND($C24="x",$A24<>""),$A24,"")
A25: Eigen veld toevoegen: zet hieronder het Windsor-veld-id in kolom A en een x in kolom C (tot rij 80).
D26: =IF(AND($C26="x",$A26<>""),$A26,"")
D27: =IF(AND($C27="x",$A27<>""),$A27,"")
D28: =IF(AND($C28="x",$A28<>""),$A28,"")
D29: =IF(AND($C29="x",$A29<>""),$A29,"")
D30: =IF(AND($C30="x",$A30<>""),$A30,"")
D31: =IF(AND($C31="x",$A31<>""),$A31,"")
D32: =IF(AND($C32="x",$A32<>""),$A32,"")
D33: =IF(AND($C33="x",$A33<>""),$A33,"")
D34: =IF(AND($C34="x",$A34<>""),$A34,"")
D35: =IF(AND($C35="x",$A35<>""),$A35,"")
D36: =IF(AND($C36="x",$A36<>""),$A36,"")
D37: =IF(AND($C37="x",$A37<>""),$A37,"")
... D80: =IF(AND($C80="x",$A80<>""),$A80,"")

Sheet Search Console dag
A1: Windsor-export: Search Console dag | C1: Status: Aanbevolen · Website → organisch zoeken (totalen)
A2: Connector | B2: searchconsole
A3: Account-id (uit Instellingen) | B3: =Instellingen!$B$13
A4: Taaknaam (Task name) | B4: ="Windsor - Sheets - Search Console dag - "&Instellingen!$B$3
A5: Tabnaam (Sheet Name) | B5: ="Search Console - dag - "&Instellingen!$B$3&" - windsor.ai" | C5: Herkenning in api/_sheetdata.js gaat op bron + niveau in deze naam; hou het voorstel aan.
A6: Columns to Match (rows to replace) | B6: date | C6: Voorstel; zoals bij de bestaande exports.
A7: Schedule | B7: Daily · 00:00 UTC · Target Cell A1 · Authentication: Google Account
A8: Query (gegenereerd — api_key blijft leeg) | B8: ="https://connectors.windsor.ai/"&$B$2&"?api_key="&IF(Instellingen!$B$4<>"","&date_preset="&Instellingen!$B$4,"")&"&fields="&_xlfn.TEXTJOIN(",",TRUE,$D$12:$D$80)&IF($B$3<>"","&select_accounts="&$B$3,"")&IF(Instellingen!$B$5<>"","&_field_headers="&Instellingen!$B$5,"")
A9: Aantal velden in de query | B9: =COUNTIF($C$12:$C$80,"x")
A11: Veld (Windsor-id) | B11: Gebruik in het dashboard | C11: Opnemen (x) | D11: → query
A12: date | B12: Datumkolom: 'Columns to Match' en periodefilter | C12: x | D12: =IF(AND($C12="x",$A12<>""),$A12,"")
A13: account_id | B13: Accountcontrole: alleen rijen van dit account tellen mee | C13: x | D13: =IF(AND($C13="x",$A13<>""),$A13,"")
A14: account_name | B14: Idem, leesbaar | C14: x | D14: =IF(AND($C14="x",$A14<>""),$A14,"")
A15: clicks | B15: Kliks | C15: x | D15: =IF(AND($C15="x",$A15<>""),$A15,"")
A16: impressions | B16: Vertoningen | C16: x | D16: =IF(AND($C16="x",$A16<>""),$A16,"")
A17: position | B17: Positie (UI weegt naar vertoningen) | C17: x | D17: =IF(AND($C17="x",$A17<>""),$A17,"")
A18: Eigen veld toevoegen: zet hieronder het Windsor-veld-id in kolom A en een x in kolom C (tot rij 80).
D19: =IF(AND($C19="x",$A19<>""),$A19,"")
D20: =IF(AND($C20="x",$A20<>""),$A20,"")
D21: =IF(AND($C21="x",$A21<>""),$A21,"")
D22: =IF(AND($C22="x",$A22<>""),$A22,"")
D23: =IF(AND($C23="x",$A23<>""),$A23,"")
D24: =IF(AND($C24="x",$A24<>""),$A24,"")
D25: =IF(AND($C25="x",$A25<>""),$A25,"")
D26: =IF(AND($C26="x",$A26<>""),$A26,"")
D27: =IF(AND($C27="x",$A27<>""),$A27,"")
D28: =IF(AND($C28="x",$A28<>""),$A28,"")
D29: =IF(AND($C29="x",$A29<>""),$A29,"")
D30: =IF(AND($C30="x",$A30<>""),$A30,"")
... D80: =IF(AND($C80="x",$A80<>""),$A80,"")

Sheet Search Console query
A1: Windsor-export: Search Console query | C1: Status: Aanbevolen · Website → zoekopdrachten
A2: Connector | B2: searchconsole
A3: Account-id (uit Instellingen) | B3: =Instellingen!$B$13
A4: Taaknaam (Task name) | B4: ="Windsor - Sheets - Search Console query - "&Instellingen!$B$3
A5: Tabnaam (Sheet Name) | B5: ="Search Console - query - "&Instellingen!$B$3&" - windsor.ai" | C5: Herkenning in api/_sheetdata.js gaat op bron + niveau in deze naam; hou het voorstel aan.
A6: Columns to Match (rows to replace) | B6: date | C6: Voorstel; zoals bij de bestaande exports.
A7: Schedule | B7: Daily · 00:00 UTC · Target Cell A1 · Authentication: Google Account
A8: Query (gegenereerd — api_key blijft leeg) | B8: ="https://connectors.windsor.ai/"&$B$2&"?api_key="&IF(Instellingen!$B$4<>"","&date_preset="&Instellingen!$B$4,"")&"&fields="&_xlfn.TEXTJOIN(",",TRUE,$D$12:$D$80)&IF($B$3<>"","&select_accounts="&$B$3,"")&IF(Instellingen!$B$5<>"","&_field_headers="&Instellingen!$B$5,"")
A9: Aantal velden in de query | B9: =COUNTIF($C$12:$C$80,"x")
A11: Veld (Windsor-id) | B11: Gebruik in het dashboard | C11: Opnemen (x) | D11: → query
A12: date | B12: Datumkolom: 'Columns to Match' en periodefilter | C12: x | D12: =IF(AND($C12="x",$A12<>""),$A12,"")
A13: account_id | B13: Accountcontrole: alleen rijen van dit account tellen mee | C13: x | D13: =IF(AND($C13="x",$A13<>""),$A13,"")
A14: account_name | B14: Idem, leesbaar | C14: x | D14: =IF(AND($C14="x",$A14<>""),$A14,"")
A15: query | B15: Zoekopdracht (kop 'Search query' of 'Query') | C15: x | D15: =IF(AND($C15="x",$A15<>""),$A15,"")
A16: clicks | B16: Kliks | C16: x | D16: =IF(AND($C16="x",$A16<>""),$A16,"")
A17: impressions | B17: Vertoningen | C17: x | D17: =IF(AND($C17="x",$A17<>""),$A17,"")
A18: position | B18: Positie | C18: x | D18: =IF(AND($C18="x",$A18<>""),$A18,"")
A19: Eigen veld toevoegen: zet hieronder het Windsor-veld-id in kolom A en een x in kolom C (tot rij 80).
D20: =IF(AND($C20="x",$A20<>""),$A20,"")
D21: =IF(AND($C21="x",$A21<>""),$A21,"")
D22: =IF(AND($C22="x",$A22<>""),$A22,"")
D23: =IF(AND($C23="x",$A23<>""),$A23,"")
D24: =IF(AND($C24="x",$A24<>""),$A24,"")
D25: =IF(AND($C25="x",$A25<>""),$A25,"")
D26: =IF(AND($C26="x",$A26<>""),$A26,"")
D27: =IF(AND($C27="x",$A27<>""),$A27,"")
D28: =IF(AND($C28="x",$A28<>""),$A28,"")
D29: =IF(AND($C29="x",$A29<>""),$A29,"")
D30: =IF(AND($C30="x",$A30<>""),$A30,"")
D31: =IF(AND($C31="x",$A31<>""),$A31,"")
... D80: =IF(AND($C80="x",$A80<>""),$A80,"")

Sheet Search Console pagina
A1: Windsor-export: Search Console pagina | C1: Status: Optioneel (anders live) · Website → pagina's
A2: Connector | B2: searchconsole
A3: Account-id (uit Instellingen) | B3: =Instellingen!$B$13
A4: Taaknaam (Task name) | B4: ="Windsor - Sheets - Search Console pagina - "&Instellingen!$B$3
A5: Tabnaam (Sheet Name) | B5: ="Search Console - pagina - "&Instellingen!$B$3&" - windsor.ai" | C5: Herkenning in api/_sheetdata.js gaat op bron + niveau in deze naam; hou het voorstel aan.
A6: Columns to Match (rows to replace) | B6: date | C6: Voorstel; zoals bij de bestaande exports.
A7: Schedule | B7: Daily · 00:00 UTC · Target Cell A1 · Authentication: Google Account
A8: Query (gegenereerd — api_key blijft leeg) | B8: ="https://connectors.windsor.ai/"&$B$2&"?api_key="&IF(Instellingen!$B$4<>"","&date_preset="&Instellingen!$B$4,"")&"&fields="&_xlfn.TEXTJOIN(",",TRUE,$D$12:$D$80)&IF($B$3<>"","&select_accounts="&$B$3,"")&IF(Instellingen!$B$5<>"","&_field_headers="&Instellingen!$B$5,"")
A9: Aantal velden in de query | B9: =COUNTIF($C$12:$C$80,"x")
A11: Veld (Windsor-id) | B11: Gebruik in het dashboard | C11: Opnemen (x) | D11: → query
A12: date | B12: Datumkolom: 'Columns to Match' en periodefilter | C12: x | D12: =IF(AND($C12="x",$A12<>""),$A12,"")
A13: account_id | B13: Accountcontrole: alleen rijen van dit account tellen mee | C13: x | D13: =IF(AND($C13="x",$A13<>""),$A13,"")
A14: account_name | B14: Idem, leesbaar | C14: x | D14: =IF(AND($C14="x",$A14<>""),$A14,"")
A15: pagepath | B15: Pagina | C15: x | D15: =IF(AND($C15="x",$A15<>""),$A15,"")
A16: clicks | B16: Kliks | C16: x | D16: =IF(AND($C16="x",$A16<>""),$A16,"")
A17: impressions | B17: Vertoningen | C17: x | D17: =IF(AND($C17="x",$A17<>""),$A17,"")
A18: position | B18: Positie | C18: x | D18: =IF(AND($C18="x",$A18<>""),$A18,"")
A19: Eigen veld toevoegen: zet hieronder het Windsor-veld-id in kolom A en een x in kolom C (tot rij 80).
D20: =IF(AND($C20="x",$A20<>""),$A20,"")
D21: =IF(AND($C21="x",$A21<>""),$A21,"")
D22: =IF(AND($C22="x",$A22<>""),$A22,"")
D23: =IF(AND($C23="x",$A23<>""),$A23,"")
D24: =IF(AND($C24="x",$A24<>""),$A24,"")
D25: =IF(AND($C25="x",$A25<>""),$A25,"")
D26: =IF(AND($C26="x",$A26<>""),$A26,"")
D27: =IF(AND($C27="x",$A27<>""),$A27,"")
D28: =IF(AND($C28="x",$A28<>""),$A28,"")
D29: =IF(AND($C29="x",$A29<>""),$A29,"")
D30: =IF(AND($C30="x",$A30<>""),$A30,"")
D31: =IF(AND($C31="x",$A31<>""),$A31,"")
... D80: =IF(AND($C80="x",$A80<>""),$A80,"")

Sheet Google Ads campagnes
A1: Windsor-export: Google Ads campagnes | C1: Status: Aanbevolen · Ads → Google Ads + ROAS
A2: Connector | B2: google_ads
A3: Account-id (uit Instellingen) | B3: =Instellingen!$B$14
A4: Taaknaam (Task name) | B4: ="Windsor - Sheets - Google Ads campagnes - "&Instellingen!$B$3
A5: Tabnaam (Sheet Name) | B5: ="Google Ads - campagnes - "&Instellingen!$B$3&" - windsor.ai" | C5: Herkenning in api/_sheetdata.js gaat op bron + niveau in deze naam; hou het voorstel aan.
A6: Columns to Match (rows to replace) | B6: date | C6: Voorstel; zoals bij de bestaande exports.
A7: Schedule | B7: Daily · 00:00 UTC · Target Cell A1 · Authentication: Google Account
A8: Query (gegenereerd — api_key blijft leeg) | B8: ="https://connectors.windsor.ai/"&$B$2&"?api_key="&IF(Instellingen!$B$4<>"","&date_preset="&Instellingen!$B$4,"")&"&fields="&_xlfn.TEXTJOIN(",",TRUE,$D$12:$D$80)&IF($B$3<>"","&select_accounts="&$B$3,"")&IF(Instellingen!$B$5<>"","&_field_headers="&Instellingen!$B$5,"")
A9: Aantal velden in de query | B9: =COUNTIF($C$12:$C$80,"x")
A11: Veld (Windsor-id) | B11: Gebruik in het dashboard | C11: Opnemen (x) | D11: → query
A12: date | B12: Datumkolom: 'Columns to Match' en periodefilter | C12: x | D12: =IF(AND($C12="x",$A12<>""),$A12,"")
A13: account_id | B13: Accountcontrole: alleen rijen van dit account tellen mee | C13: x | D13: =IF(AND($C13="x",$A13<>""),$A13,"")
A14: account_name | B14: Idem, leesbaar | C14: x | D14: =IF(AND($C14="x",$A14<>""),$A14,"")
